Workbook

Sheet Hiring Companies
A1: S.No | B1: Company | C1: Role | D1: Location | E1: Platform | F1: Posted | G1: Apply Link | H1: Match | I1: Notes | J1: Mode | K1: Exp Fit (4 yr)
A2: 1 | B2: YMinds.AI | C2: Senior Python Backend Developer - AI/ML (4+ yrs) | D2: Remote | E2: LinkedIn | F2: 2026 | G2: =HYPERLINK("https://in.linkedin.com/jobs/view/senior-python-backend-developer-ai-ml-4+-years-experience-immediate-joiner-remote-at-yminds-ai-4387945955","Apply") | H2: Tight | I2: Exact title + exp match | J2: Remote | K2: Ideal (3-6 yr)
A3: 2 | B3: HireTo Co. | C3: Senior Backend Developer Python/Django | D3: India | E3: LinkedIn | F3: 2026 | G3: =HYPERLINK("https://in.linkedin.com/jobs/senior-backend-developer-python-django-jobs","Apply") | H3: Tight | I3: From LinkedIn search aggregator | J3: Varies | K3: Ideal (3-6 yr)
A4: 3 | B4: Solvex Solutions | C4: Senior Backend Developer Python/Django | D4: India | E4: LinkedIn | F4: 2026 | G4: =HYPERLINK("https://in.linkedin.com/jobs/senior-backend-developer-python-django-jobs","Apply") | H4: Tight | J4: Varies | K4: Ideal (3-6 yr)
A5: 4 | B5: Hexatic | C5: Senior Backend Developer Python/Django | D5: India | E5: LinkedIn | F5: 2026 | G5: =HYPERLINK("https://in.linkedin.com/jobs/senior-backend-developer-python-django-jobs","Apply") | H5: Tight | J5: Varies | K5: Ideal (3-6 yr)
A6: 5 | B6: VGreen Technology Solutions | C6: Senior Backend Developer Python/Django | D6: India | E6: LinkedIn | F6: 2026 | G6: =HYPERLINK("https://in.linkedin.com/jobs/senior-backend-developer-python-django-jobs","Apply") | H6: Tight | J6: Varies | K6: Ideal (3-6 yr)
A7: 6 | B7: Schneider Electric | C7: Senior Backend Developer Python/Django | D7: India | E7: LinkedIn | F7: 2026 | G7: =HYPERLINK("https://in.linkedin.com/jobs/senior-backend-developer-python-django-jobs","Apply") | H7: Tight | I7: Global MNC | J7: Varies | K7: Ideal (3-6 yr)
A8: 7 | B8: Rentokil Initial | C8: Senior Backend Developer Python/Django | D8: India | E8: LinkedIn | F8: 2026 | G8: =HYPERLINK("https://in.linkedin.com/jobs/senior-backend-developer-python-django-jobs","Apply") | H8: Reasonable | J8: Varies | K8: Ideal (3-6 yr)
A9: 8 | B9: Arctic Wolf | C9: Senior Backend Developer Python/Django | D9: India | E9: LinkedIn | F9: 2026 | G9: =HYPERLINK("https://in.linkedin.com/jobs/senior-backend-developer-python-django-jobs","Apply") | H9: Tight | I9: Cybersecurity product | J9: Varies | K9: Ideal (3-6 yr)
A10: 9 | B10: Miba Group | C10: Senior Backend Developer Python/Django | D10: India | E10: LinkedIn | F10: 2026 | G10: =HYPERLINK("https://in.linkedin.com/jobs/senior-backend-developer-python-django-jobs","Apply") | H10: Reasonable | J10: Varies | K10: Ideal (3-6 yr)
A11: 10 | B11: vueverse | C11: Senior Python Backend Developer | D11: India | E11: Cutshort | F11: 2026 | G11: =HYPERLINK("https://cutshort.io/jobs/senior-python-developer-jobs","Apply") | H11: Tight | J11: Varies | K11: Ideal (3-6 yr)
A12: 11 | B12: Infomanav | C12: Senior Python Backend Developer | D12: India | E12: Cutshort | F12: 2026 | G12: =HYPERLINK("https://cutshort.io/jobs/senior-python-developer-jobs","Apply") | H12: Tight | J12: Varies | K12: Ideal (3-6 yr)
A13: 12 | B13: SolutionChamps DesignLabs | C13: Senior Python Backend Developer | D13: India | E13: Cutshort | F13: 2026 | G13: =HYPERLINK("https://cutshort.io/jobs/senior-python-developer-jobs","Apply") | H13: Tight | J13: Varies | K13: Ideal (3-6 yr)
A14: 13 | B14: Syneos Health | C14: Senior Python Backend Developer | D14: India | E14: Cutshort | F14: 2026 | G14: =HYPERLINK("https://cutshort.io/jobs/senior-python-developer-jobs","Apply") | H14: Tight | I14: Pharma/CRO | J14: Varies | K14: Ideal (3-6 yr)
A15: 14 | B15: Intellectsoft | C15: Senior Python Backend Developer | D15: India | E15: Cutshort | F15: 2026 | G15: =HYPERLINK("https://cutshort.io/jobs/senior-python-developer-jobs","Apply") | H15: Tight | J15: Varies | K15: Ideal (3-6 yr)
A16: 15 | B16: Dataviv Technologies | C16: Senior Python Backend Developer | D16: India | E16: Cutshort | F16: 2026 | G16: =HYPERLINK("https://cutshort.io/jobs/senior-python-developer-jobs","Apply") | H16: Tight | J16: Varies | K16: Ideal (3-6 yr)
A17: 16 | B17: ChicMic Studios | C17: Senior Python Backend Developer | D17: India | E17: Cutshort | F17: 2026 | G17: =HYPERLINK("https://cutshort.io/jobs/senior-python-developer-jobs","Apply") | H17: Tight | J17: Varies | K17: Ideal (3-6 yr)
A18: 17 | B18: 6sense | C18: Python Developer - Backend (Remote) | D18: Remote | E18: Cutshort | F18: 2026 | G18: =HYPERLINK("https://cutshort.io/job/Python-Developer-Backend-6sense-z5mniNnd","Apply") | H18: Tight | I18: Product company | J18: Remote | K18: Ideal (3-6 yr)
A19: 18 | B19: Skyloov Property Portal | C19: Senior Python Developer | D19: Remote | E19: Indeed | F19: 2026-06-16 | G19: =HYPERLINK("https://to.indeed.com/aashyhnzhqkz","Apply") | H19: Tight | I19: ★ NEW Freshly posted | J19: Remote | K19: Ideal (3-6 yr)
A20: 19 | B20: Valiant Systems | C20: Senior Python Developer | D20: Chennai (Porur) | E20: Indeed | F20: 2026-07-13 | G20: =HYPERLINK("https://to.indeed.com/aa89qvp66ggl","Apply") | H20: Tight | I20: ★ Pan-India Chennai | J20: Onsite | K20: Ideal (3-6 yr)
A21: 20 | B21: AEVEVO Technology | C21: Senior React/Django Developer | D21: Chennai | E21: Indeed | F21: 2026-08-01 | G21: =HYPERLINK("https://to.indeed.com/aayqpws9vd8d","Apply") | H21: Reasonable | I21: ★ Pan-India Chennai — Django, freshest | J21: Onsite | K21: Ideal (3-6 yr)
A22: 21 | B22: Accenture | C22: AI/ML Computational Science Sr Analyst | D22: Chennai | E22: Indeed | F22: 2026-07-09 | G22: =HYPERLINK("https://to.indeed.com/aakqq4hygdvt","Apply") | H22: Reasonable | I22: ★ Pan-India Chennai — AI/ML | J22: Onsite/Hybrid | K22: Ideal (3-6 yr)
A23: 22 | B23: InterProducTec Virtual Labs | C23: Sr. Python Backend Developer | D23: Navi Mumbai (Airoli) | E23: Indeed | F23: 2026-07-14 | G23: =HYPERLINK("https://to.indeed.com/aazghkbhv4s6","Apply") | H23: Tight | I23: ★ Pan-India Mumbai — exact title | J23: Onsite/Hybrid | K23: Ideal (3-6 yr)
A24: 23 | B24: DSMD.inc | C24: Senior Python Developer | D24: Mumbai | E24: Indeed | F24: 2026-07-15 | G24: =HYPERLINK("https://to.indeed.com/aa2cvvqpwhy2","Apply") | H24: Tight | I24: ★ Pan-India Mumbai | J24: Onsite/Hybrid | K24: Ideal (3-6 yr)
A25: 24 | B25: Proximus | C25: Python Developer | D25: Mumbai | E25: Indeed | F25: 2026-07-23 | G25: =HYPERLINK("https://to.indeed.com/aak6ksy7lxsy","Apply") | H25: Reasonable | I25: ★ Pan-India Mumbai | J25: Onsite/Hybrid | K25: Ideal (3-6 yr)
A26: 25 | B26: The Propertist | C26: Senior Full Stack Engineer | D26: Mumbai | E26: Indeed | F26: 2026-07-14 | G26: =HYPERLINK("https://to.indeed.com/aampsr7ls8fd","Apply") | H26: Reasonable | I26: ★ Pan-India Mumbai | J26: Onsite | K26: Ideal (3-6 yr)
A27: 26 | B27: PwC | C27: Senior Associate — Python Developer (GCC Advisory) | D27: Kolkata | E27: Indeed | F27: 2026-07-08 | G27: =HYPERLINK("https://to.indeed.com/aak828bhv2sl","Apply") | H27: Reasonable | I27: ★ Pan-India Kolkata — Big-4 brand | J27: Onsite/Hybrid | K27: Ideal (3-6 yr)
A28: 27 | B28: Proclivity Digitech | C28: Senior AI & AWS Claude Full Stack Developer | D28: Kolkata | E28: Indeed | F28: 2026-07-15 | G28: =HYPERLINK("https://to.indeed.com/aa8y7p8r87zy","Apply") | H28: Reasonable | I28: ★ Pan-India Kolkata — Claude/AWS, agentic-AI fit | J28: Onsite | K28: Ideal (3-6 yr)
A29: 28 | B29: Techno Wise (India) | C29: Python Full Stack Developer | D29: Kolkata | E29: Indeed | F29: 2026-07-30 | G29: =HYPERLINK("https://to.indeed.com/aamwm7dndjnp","Apply") | H29: Reasonable | I29: ★ Pan-India Kolkata | J29: Onsite | K29: Ideal (3-6 yr)
A30: 29 | B30: Team HR | C30: Senior Python Developer | D30: Ahmedabad | E30: Indeed | F30: 2026-07-20 | G30: =HYPERLINK("https://to.indeed.com/aa9xxlv6p6cv","Apply") | H30: Tight | I30: ★ Pan-India Ahmedabad | J30: Onsite/Hybrid | K30: Ideal (3-6 yr)
A31: 30 | B31: ManekTech | C31: Sr. AIML Developer | D31: Ahmedabad | E31: Indeed | F31: 2026-07-24 | G31: =HYPERLINK("https://to.indeed.com/aawcfs6264fd","Apply") | H31: Reasonable | I31: ★ Pan-India Ahmedabad — AI/ML | J31: Onsite | K31: Ideal (3-6 yr)
A32: 31 | B32: Orangedatatech | C32: Senior Python Developer | D32: Indore | E32: Indeed | F32: 2026-07-22 | G32: =HYPERLINK("https://to.indeed.com/aam7xnvzwddq","Apply") | H32: Tight | I32: ★ Pan-India Indore | J32: Onsite | K32: Ideal (3-6 yr)
A33: 32 | B33: Shastika Global Impex | C33: Senior Python Developer | D33: Coimbatore | E33: Indeed | F33: 2026-07-23 | G33: =HYPERLINK("https://to.indeed.com/aa9jsx4hmvzt","Apply") | H33: Reasonable | I33: ★ Pan-India Coimbatore | J33: Onsite | K33: Ideal (3-6 yr)
A34: 33 | B34: HelixBeat | C34: Senior Engineer — Python, Django/FastAPI, Airflow/PySpark | D34: Remote | E34: Indeed | F34: 2026-07-29 | G34: =HYPERLINK("https://to.indeed.com/aaywk8glgdcn","Apply") | H34: Tight | I34: ★ Pan-India Remote — exact stack match | J34: Remote | K34: Ideal (3-6 yr)
A35: 34 | B35: Immersive Infotech | C35: Sr. Python Developer | D35: Remote | E35: Indeed | F35: 2026-07-29 | G35: =HYPERLINK("https://to.indeed.com/aafcbjmfzrcx","Apply") | H35: Tight | I35: ★ Pan-India Remote | J35: Remote | K35: Ideal (3-6 yr)
A36: 35 | B36: iVA TEK | C36: Full-Stack / Backend Developer | D36: Remote | E36: Indeed | F36: 2026-06-24 | G36: =HYPERLINK("https://to.indeed.com/aabjskzjgz72","Apply") | H36: Reasonable | I36: ★ Pan-India Remote | J36: Remote | K36: Ideal (3-6 yr)
A37: 36 | B37: Aura Recruitment Solutions | C37: Senior AI Developer | D37: Remote | E37: Indeed | F37: 2026-07-20 | G37: =HYPERLINK("https://to.indeed.com/aa22n488qphm","Apply") | H37: Reasonable | I37: ★ Refresh Recruiter-posted, AI | J37: Remote | K37: Ideal (3-6 yr)
A38: 37 | B38: New Media Guru | C38: Senior Python Developer | D38: Gurugram | E38: Indeed | F38: 2026-07-15 | G38: =HYPERLINK("https://to.indeed.com/aasxks6njtwd","Apply") | H38: Tight | I38: ★ Refresh Gurugram | J38: Onsite/Hybrid | K38: Ideal (3-6 yr)
A39: 38 | B39: AWC Software | C39: Senior Developer – Backend | D39: Gurugram | E39: Indeed | F39: 2026-07-07 | G39: =HYPERLINK("https://to.indeed.com/aapvjgg8wcg8","Apply") | H39: Tight | I39: ★ Refresh Gurugram | J39: Onsite/Hybrid | K39: Ideal (3-6 yr)
A40: 39 | B40: Fluper Ltd | C40: Python Developer with LLM | D40: Noida | E40: Indeed | F40: 2026-07-20 | G40: =HYPERLINK("https://to.indeed.com/aab64mv66jkj","Apply") | H40: Tight | I40: ★ Refresh LLM — agentic-AI fit | J40: Onsite/Hybrid | K40: Ideal (3-6 yr)
...

Sheet Priority
A1: PRIORITY LIST — Python Backend Developer (~4 yr) · Tight + Ideal · LIVE only
A3: # | B3: Company | C3: Role / Title | D3: Location | E3: Mode | F3: Posted | G3: Match | H3: Exp Fit | I3: Apply
A4: 1 | B4: YMinds.AI | C4: Senior Python Backend Developer - AI/ML (4+ yrs) | D4: Remote | E4: Remote | F4: 2026 | G4: Tight | H4: Ideal | I4: =HYPERLINK("https://in.linkedin.com/jobs/view/senior-python-backend-developer-ai-ml-4+-years-experience-immediate-joiner-remote-at-yminds-ai-4387945955","Apply")
A5: 2 | B5: 6sense | C5: Python Developer - Backend (Remote) | D5: Remote | E5: Remote | F5: 2026 | G5: Tight | H5: Ideal | I5: =HYPERLINK("https://cutshort.io/job/Python-Developer-Backend-6sense-z5mniNnd","Apply")
A6: 3 | B6: Skyloov Property Portal | C6: Senior Python Developer | D6: Remote | E6: Remote | F6: 2026-06-16 | G6: Tight | H6: Ideal | I6: =HYPERLINK("https://to.indeed.com/aashyhnzhqkz","Apply")
A7: 4 | B7: HelixBeat | C7: Senior Engineer — Python, Django/FastAPI, Airflow/PySpark | D7: Remote | E7: Remote | F7: 2026-07-29 | G7: Tight | H7: Ideal | I7: =HYPERLINK("https://to.indeed.com/aaywk8glgdcn","Apply")
A8: 5 | B8: Immersive Infotech | C8: Sr. Python Developer | D8: Remote | E8: Remote | F8: 2026-07-29 | G8: Tight | H8: Ideal | I8: =HYPERLINK("https://to.indeed.com/aafcbjmfzrcx","Apply")
A9: 6 | B9: Team HR | C9: Senior Python Developer | D9: Ahmedabad | E9: Onsite/Hybrid | F9: 2026-07-20 | G9: Tight | H9: Ideal | I9: =HYPERLINK("https://to.indeed.com/aa9xxlv6p6cv","Apply")
A10: 7 | B10: New Media Guru | C10: Senior Python Developer | D10: Gurugram | E10: Onsite/Hybrid | F10: 2026-07-15 | G10: Tight | H10: Ideal | I10: =HYPERLINK("https://to.indeed.com/aasxks6njtwd","Apply")
A11: 8 | B11: AWC Software | C11: Senior Developer – Backend | D11: Gurugram | E11: Onsite/Hybrid | F11: 2026-07-07 | G11: Tight | H11: Ideal | I11: =HYPERLINK("https://to.indeed.com/aapvjgg8wcg8","Apply")
A12: 9 | B12: DSMD.inc | C12: Senior Python Developer | D12: Mumbai | E12: Onsite/Hybrid | F12: 2026-07-15 | G12: Tight | H12: Ideal | I12: =HYPERLINK("https://to.indeed.com/aa2cvvqpwhy2","Apply")
A13: 10 | B13: InterProducTec Virtual Labs | C13: Sr. Python Backend Developer | D13: Navi Mumbai (Airoli) | E13: Onsite/Hybrid | F13: 2026-07-14 | G13: Tight | H13: Ideal | I13: =HYPERLINK("https://to.indeed.com/aazghkbhv4s6","Apply")
A14: 11 | B14: Fluper Ltd | C14: Python Developer with LLM | D14: Noida | E14: Onsite/Hybrid | F14: 2026-07-20 | G14: Tight | H14: Ideal | I14: =HYPERLINK("https://to.indeed.com/aab64mv66jkj","Apply")
A15: 12 | B15: Valiant Systems | C15: Senior Python Developer | D15: Chennai (Porur) | E15: Onsite | F15: 2026-07-13 | G15: Tight | H15: Ideal | I15: =HYPERLINK("https://to.indeed.com/aa89qvp66ggl","Apply")
A16: 13 | B16: Orangedatatech | C16: Senior Python Developer | D16: Indore | E16: Onsite | F16: 2026-07-22 | G16: Tight | H16: Ideal | I16: =HYPERLINK("https://to.indeed.com/aam7xnvzwddq","Apply")
A17: 14 | B17: HireTo Co. | C17: Senior Backend Developer Python/Django | D17: India | E17: Varies | F17: 2026 | G17: Tight | H17: Ideal | I17: =HYPERLINK("https://in.linkedin.com/jobs/senior-backend-developer-python-django-jobs","Apply")
A18: 15 | B18: Solvex Solutions | C18: Senior Backend Developer Python/Django | D18: India | E18: Varies | F18: 2026 | G18: Tight | H18: Ideal | I18: =HYPERLINK("https://in.linkedin.com/jobs/senior-backend-developer-python-django-jobs","Apply")
A19: 16 | B19: Hexatic | C19: Senior Backend Developer Python/Django | D19: India | E19: Varies | F19: 2026 | G19: Tight | H19: Ideal | I19: =HYPERLINK("https://in.linkedin.com/jobs/senior-backend-developer-python-django-jobs","Apply")
A20: 17 | B20: VGreen Technology Solutions | C20: Senior Backend Developer Python/Django | D20: India | E20: Varies | F20: 2026 | G20: Tight | H20: Ideal | I20: =HYPERLINK("https://in.linkedin.com/jobs/senior-backend-developer-python-django-jobs","Apply")
A21: 18 | B21: Schneider Electric | C21: Senior Backend Developer Python/Django | D21: India | E21: Varies | F21: 2026 | G21: Tight | H21: Ideal | I21: =HYPERLINK("https://in.linkedin.com/jobs/senior-backend-developer-python-django-jobs","Apply")
A22: 19 | B22: Arctic Wolf | C22: Senior Backend Developer Python/Django | D22: India | E22: Varies | F22: 2026 | G22: Tight | H22: Ideal | I22: =HYPERLINK("https://in.linkedin.com/jobs/senior-backend-developer-python-django-jobs","Apply")
A23: 20 | B23: vueverse | C23: Senior Python Backend Developer | D23: India | E23: Varies | F23: 2026 | G23: Tight | H23: Ideal | I23: =HYPERLINK("https://cutshort.io/jobs/senior-python-developer-jobs","Apply")
A24: 21 | B24: Infomanav | C24: Senior Python Backend Developer | D24: India | E24: Varies | F24: 2026 | G24: Tight | H24: Ideal | I24: =HYPERLINK("https://cutshort.io/jobs/senior-python-developer-jobs","Apply")
A25: 22 | B25: SolutionChamps DesignLabs | C25: Senior Python Backend Developer | D25: India | E25: Varies | F25: 2026 | G25: Tight | H25: Ideal | I25: =HYPERLINK("https://cutshort.io/jobs/senior-python-developer-jobs","Apply")
A26: 23 | B26: Syneos Health | C26: Senior Python Backend Developer | D26: India | E26: Varies | F26: 2026 | G26: Tight | H26: Ideal | I26: =HYPERLINK("https://cutshort.io/jobs/senior-python-developer-jobs","Apply")
A27: 24 | B27: Intellectsoft | C27: Senior Python Backend Developer | D27: India | E27: Varies | F27: 2026 | G27: Tight | H27: Ideal | I27: =HYPERLINK("https://cutshort.io/jobs/senior-python-developer-jobs","Apply")
A28: 25 | B28: Dataviv Technologies | C28: Senior Python Backend Developer | D28: India | E28: Varies | F28: 2026 | G28: Tight | H28: Ideal | I28: =HYPERLINK("https://cutshort.io/jobs/senior-python-developer-jobs","Apply")
A29: 26 | B29: ChicMic Studios | C29: Senior Python Backend Developer | D29: India | E29: Varies | F29: 2026 | G29: Tight | H29: Ideal | I29: =HYPERLINK("https://cutshort.io/jobs/senior-python-developer-jobs","Apply")

Sheet Job Search Links
A1: LIVE JOB-SEARCH LINKS — Python Backend Developer (4 yr) · India
A2: Click "Open Search" to run a pre-filled, live search on each site. (Some need login: LinkedIn, Instahyre, Wellfound.)
A4: # | B4: Site | C4: What it searches | D4: Note | E4: Open Search
A5: 1 | B5: LinkedIn | C5: Senior Python Backend Developer · India · Mid-Senior | D5: Best for network + recruiters | E5: =HYPERLINK("https://www.linkedin.com/jobs/search/?keywords=Senior%20Python%20Backend%20Developer&location=India&f_E=3%2C4&f_TPR=r604800","Open Search")
A6: 2 | B6: LinkedIn (Remote) | C6: Python Backend Developer · India · Remote | D6: Remote-only filter (f_WT=2) | E6: =HYPERLINK("https://www.linkedin.com/jobs/search/?keywords=Python%20Backend%20Developer&location=India&f_E=3%2C4&f_WT=2","Open Search")
A7: 3 | B7: Naukri | C7: Senior Python Backend Developer · 4 yr exp | D7: India’s biggest job board | E7: =HYPERLINK("https://www.naukri.com/senior-python-backend-developer-jobs?experience=4","Open Search")
A8: 4 | B8: Naukri (Remote) | C8: Python Backend Developer · Remote | D8: Remote roles on Naukri | E8: =HYPERLINK("https://www.naukri.com/python-backend-developer-jobs?wfhType=1","Open Search")
A9: 5 | B9: Indeed India | C9: Senior Python Backend Developer · India | D9: Broad aggregator | E9: =HYPERLINK("https://in.indeed.com/jobs?q=Senior+Python+Backend+Developer&l=India","Open Search")
A10: 6 | B10: Indeed (Remote) | C10: Python Backend Developer · Remote | D10: Remote-only | E10: =HYPERLINK("https://in.indeed.com/jobs?q=Python+Backend+Developer&l=Remote","Open Search")
A11: 7 | B11: Instahyre | C11: Python Backend Developer | D11: Curated, recruiter-reachout (login) | E11: =HYPERLINK("https://www.instahyre.com/search-jobs/?q=Python+Backend+Developer","Open Search")
A12: 8 | B12: Cutshort | C12: Senior Python Backend Developer | D12: AI-matched startup roles | E12: =HYPERLINK("https://cutshort.io/jobs/senior-python-backend-developer-jobs","Open Search")
A13: 9 | B13: Hirist | C13: Python Backend Developer | D13: Tech-only India job board | E13: =HYPERLINK("https://www.hirist.tech/search/python-backend-developer-jobs","Open Search")
A14: 10 | B14: Wellfound | C14: Backend Engineer (Python) · startups | D14: AngelList startup jobs (login) | E14: =HYPERLINK("https://wellfound.com/role/r/backend-engineer","Open Search")

Sheet Summary
A1: Metric | B1: Value
A2: Total openings tracked | B2: =COUNTA('Hiring Companies'!B2:B250)
A3: Unique companies | B3: =SUMPRODUCT(1/COUNTIF('Hiring Companies'!B2:B250,'Hiring Companies'!B2:B250))
A4: Tight matches | B4: =COUNTIF('Hiring Companies'!H2:H250,"Tight")
A5: Reasonable matches | B5: =COUNTIF('Hiring Companies'!H2:H250,"Reasonable")
A6: Loose matches | B6: =COUNTIF('Hiring Companies'!H2:H250,"Loose")
A8: Platform | B8: Count
A9: Indeed | B9: =COUNTIF('Hiring Companies'!E2:E250,"Indeed")
A10: LinkedIn | B10: =COUNTIF('Hiring Companies'!E2:E250,"LinkedIn")
A11: Cutshort | B11: =COUNTIF('Hiring Companies'!E2:E250,"Cutshort")
A12: Naukri | B12: =COUNTIF('Hiring Companies'!E2:E250,"Naukri")
A14: Location | B14: Count
A15: Bangalore | B15: =COUNTIF('Hiring Companies'!D2:D250,"Bangalore")
A16: Hyderabad | B16: =COUNTIF('Hiring Companies'!D2:D250,"Hyderabad")
A17: Delhi | B17: =COUNTIF('Hiring Companies'!D2:D250,"Delhi")
A18: Chandigarh | B18: =COUNTIF('Hiring Companies'!D2:D250,"Chandigarh")
A19: Pune | B19: =COUNTIF('Hiring Companies'!D2:D250,"Pune")
A20: Remote | B20: =COUNTIF('Hiring Companies'!D2:D250,"Remote")
A21: India | B21: =COUNTIF('Hiring Companies'!D2:D250,"India")
A22: Kharar, Punjab | B22: =COUNTIF('Hiring Companies'!D2:D250,"Kharar, Punjab")
A24: Experience fit (4-yr profile)
A25: Ideal (3-6 yr) — your level | B25: =COUNTIF('Hiring Companies'!K2:K250,"Ideal (3-6 yr)")
A26: Stretch (lead / 8+ yr) | B26: =COUNTIF('Hiring Companies'!K2:K250,"Stretch (lead/8+)")
A27: Below (jr / intern) | B27: =COUNTIF('Hiring Companies'!K2:K250,"Below (jr/intern)")
A28: PRIORITY (Tight + Ideal) | B28: =COUNTIFS('Hiring Companies'!H2:H250,"Tight",'Hiring Companies'!K2:K250,"Ideal (3-6 yr)")

Sheet Notes
A1: About this list
A2: Compiled across Indeed (direct API), LinkedIn search, Cutshort, and Naukri search.
A3: Naukri direct fetch was blocked (HTTP 403); LinkedIn aggregator pages used in lieu of authenticated access.
A5: Match strength legend
A6: Tight = Senior + Python + Backend in title/JD, fits 4 yrs
A7: Reasonable = Senior Python-leaning role, may need stack alignment
A8: Loose = Adjacent stack (Java/.NET/Golang/QA/Frontend) — pivot only
A10: Coverage caveats
A11: Indeed: ~28 unique companies returned across 6 geos (paginated sample, not full set)
A12: LinkedIn India aggregate: 10,000+ Senior Python; 812 Python Django Backend; 129 Senior Backend Python/Django
A13: Cutshort: 7 live 'Senior Python Backend' roles; 50+ across broader Backend/Python listings
A14: Naukri Bangalore (Python, all-level): 60,711 listings
... A27: Cleanup on 2026-08-13 — removed 83 postings older than 60 days (likely expired) to "Expired (archived)" tab. 42 live roles remain. Date-based (not click-verified).

Sheet Expired (archived)
A1: S.No | B1: Company | C1: Role | D1: Location | E1: Platform | F1: Posted | G1: Apply | H1: Match | I1: Notes | J1: Mode | K1: Exp Fit | L1: Age (days)
A2: 1 | B2: Citi | C2: Python Backend Developer | D2: Pune | E2: Indeed | F2: 2026-03-30 | G2: =HYPERLINK("https://to.indeed.com/aawb6kf28mhg","Apply") | H2: Tight | I2: MNC bank — strong Python backend role | J2: Onsite/Hybrid | K2: Ideal (3-6 yr) | L2: 136
A3: 2 | B3: Sketchwire | C3: Senior Backend Developer - Python | D3: Kharar, Punjab | E3: Indeed | F3: 2026-06-01 | G3: =HYPERLINK("https://to.indeed.com/aanj2827cdqv","Apply") | H3: Tight | I3: Exact title match | J3: Onsite/Hybrid | K3: Ideal (3-6 yr) | L3: 73
A4: 3 | B4: Halliburton | C4: Backend Developer (K3S/K8S/Docker) | D4: Bangalore | E4: Indeed | F4: 2026-06-09 | G4: =HYPERLINK("https://to.indeed.com/aaqt7ypn7blw","Apply") | H4: Tight | I4: Energy MNC — backend + K8s | J4: Onsite/Hybrid | K4: Ideal (3-6 yr) | L4: 65
A5: 4 | B5: nference | C5: Senior Software Engineer - Backend | D5: Bangalore | E5: Indeed | F5: 2026-05-05 | G5: =HYPERLINK("https://to.indeed.com/aahslp4q7jg9","Apply") | H5: Tight | I5: AI/biotech product company | J5: Onsite/Hybrid | K5: Ideal (3-6 yr) | L5: 100
A6: 5 | B6: Sapiens | C6: Lead Developer - R&D | D6: Bangalore | E6: Indeed | F6: 2026-06-08 | G6: =HYPERLINK("https://to.indeed.com/aahgp9fy2gc4","Apply") | H6: Reasonable | I6: Insurance-tech product | J6: Onsite/Hybrid | K6: Stretch (lead/8+) | L6: 66
A7: 6 | B7: Accenture | C7: Custom Software Engineer | D7: Bangalore | E7: Indeed | F7: 2026-03-04 | G7: =HYPERLINK("https://to.indeed.com/aax2h8rt7s7p","Apply") | H7: Reasonable | I7: Consulting — broad Python work | J7: Onsite/Hybrid | K7: Ideal (3-6 yr) | L7: 162
A8: 7 | B8: The Wedding Company | C8: Senior Software Engineer | D8: Bangalore | E8: Indeed | F8: 2026-02-28 | G8: =HYPERLINK("https://to.indeed.com/aal2hy2z8x4w","Apply") | H8: Reasonable | J8: Onsite/Hybrid | K8: Ideal (3-6 yr) | L8: 166
A9: 8 | B9: SCSK Asia Pacific | C9: Senior Full Stack Developer | D9: Bangalore | E9: Indeed | F9: 2026-06-04 | G9: =HYPERLINK("https://to.indeed.com/aagss84qbnpf","Apply") | H9: Reasonable | I9: Python full-stack | J9: Onsite/Hybrid | K9: Ideal (3-6 yr) | L9: 70
A10: 9 | B10: SCSK Asia Pacific | C10: Full Stack Developer | D10: Bangalore | E10: Indeed | F10: 2026-06-04 | G10: =HYPERLINK("https://to.indeed.com/aadwntlgkfht","Apply") | H10: Reasonable | J10: Onsite/Hybrid | K10: Ideal (3-6 yr) | L10: 70
A11: 10 | B11: Miror Therapeutics | C11: Senior Full Stack Developer | D11: Bangalore | E11: Indeed | F11: 2026-06-04 | G11: =HYPERLINK("https://to.indeed.com/aayfnxvwnxlh","Apply") | H11: Reasonable | I11: HealthTech | J11: Onsite/Hybrid | K11: Ideal (3-6 yr) | L11: 70
A12: 11 | B12: ANSR Source | C12: Senior Full Stack Developer MERN | D12: Bangalore | E12: Indeed | F12: 2026-05-18 | G12: =HYPERLINK("https://to.indeed.com/aar4tnc96n8l","Apply") | H12: Loose | I12: MERN — adjacent | J12: Onsite/Hybrid | K12: Ideal (3-6 yr) | L12: 87
A13: 12 | B13: KJBN Labs | C13: Software Engineer - Golang | D13: Bangalore | E13: Indeed | F13: 2026-03-03 | G13: =HYPERLINK("https://to.indeed.com/aashtd4lywrx","Apply") | H13: Loose | I13: Golang — adjacent | J13: Onsite/Hybrid | K13: Ideal (3-6 yr) | L13: 163
A14: 13 | B14: DDiSmart | C14: Sr. Python Developer | D14: Hyderabad | E14: Indeed | F14: 2026-05-20 | G14: =HYPERLINK("https://to.indeed.com/aa6thgmyzqtv","Apply") | H14: Tight | I14: Direct title match | J14: Onsite/Hybrid | K14: Ideal (3-6 yr) | L14: 85
A15: 14 | B15: In2IT Enterprise | C15: Python Developer | D15: Hyderabad | E15: Indeed | F15: 2025-12-31 | G15: =HYPERLINK("https://to.indeed.com/aad7h4crbjcg","Apply") | H15: Tight | J15: Onsite/Hybrid | K15: Ideal (3-6 yr) | L15: 225
A16: 15 | B16: Broadcom | C16: Senior Software Architect | D16: Hyderabad | E16: Indeed | F16: 2026-04-15 | G16: =HYPERLINK("https://to.indeed.com/aa9ys67dr4px","Apply") | H16: Reasonable | I16: Senior architect | J16: Onsite/Hybrid | K16: Stretch (lead/8+) | L16: 120
A17: 16 | B17: Teradata | C17: Senior Software Engineer | D17: Hyderabad | E17: Indeed | F17: 2026-05-07 | G17: =HYPERLINK("https://to.indeed.com/aaj4gmnb68yk","Apply") | H17: Reasonable | I17: Data product | J17: Onsite/Hybrid | K17: Ideal (3-6 yr) | L17: 98
A18: 17 | B18: Dataflix | C18: Senior AI Developer | D18: Hyderabad | E18: Indeed | F18: 2026-03-03 | G18: =HYPERLINK("https://to.indeed.com/aajpwpgl7nzc","Apply") | H18: Reasonable | I18: AI-leaning | J18: Onsite/Hybrid | K18: Ideal (3-6 yr) | L18: 163
A19: 18 | B19: Novartis | C19: Senior Analyst - Agentforce | D19: Hyderabad | E19: Indeed | F19: 2026-05-22 | G19: =HYPERLINK("https://to.indeed.com/aagxxdnrrl7j","Apply") | H19: Loose | I19: Salesforce Agentforce | J19: Onsite/Hybrid | K19: Ideal (3-6 yr) | L19: 83
A20: 19 | B20: Invesco | C20: Adv Engineer QE II | D20: Hyderabad | E20: Indeed | F20: 2026-06-09 | G20: =HYPERLINK("https://to.indeed.com/aaxv8jm78kl9","Apply") | H20: Loose | I20: QA/QE | J20: Onsite/Hybrid | K20: Ideal (3-6 yr) | L20: 65
A21: 20 | B21: CGI | C21: Java Backend Developer | D21: Hyderabad | E21: Indeed | F21: 2026-06-04 | G21: =HYPERLINK("https://to.indeed.com/aahj84bmf7lw","Apply") | H21: Loose | I21: Java — not Python | J21: Onsite/Hybrid | K21: Ideal (3-6 yr) | L21: 70
A22: 21 | B22: AppsTek Corp | C22: Senior QA Automation Test Lead | D22: Hyderabad | E22: Indeed | F22: 2026-02-28 | G22: =HYPERLINK("https://to.indeed.com/aalxqhzhyzl4","Apply") | H22: Loose | I22: QA automation | J22: Onsite/Hybrid | K22: Stretch (lead/8+) | L22: 166
A23: 22 | B23: Plane Software | C23: Junior Frontend Engineer | D23: Hyderabad | E23: Indeed | F23: 2026-04-22 | G23: =HYPERLINK("https://to.indeed.com/aa4dqfkxt69s","Apply") | H23: Loose | I23: Frontend | J23: Onsite/Hybrid | K23: Below (jr/intern) | L23: 113
A24: 23 | B24: Trinity Business Solutions | C24: Senior AI/ML Developer | D24: Delhi | E24: Indeed | F24: 2026-03-29 | G24: =HYPERLINK("https://to.indeed.com/aa7pnzfvzddk","Apply") | H24: Reasonable | I24: AI/ML | J24: Onsite/Hybrid | K24: Ideal (3-6 yr) | L24: 137
A25: 24 | B25: Krishna Hiring Services | C25: Technical Team Lead (Python) | D25: Chandigarh | E25: Indeed | F25: 2025-12-19 | G25: =HYPERLINK("https://to.indeed.com/aarzjptwjcdg","Apply") | H25: Tight | I25: Python backend team lead | J25: Onsite/Hybrid | K25: Stretch (lead/8+) | L25: 237
A26: 25 | B26: Allengers Infotech | C26: Sr ASP.Net Developer / Team Lead | D26: Chandigarh | E26: Indeed | F26: 2026-02-26 | G26: =HYPERLINK("https://to.indeed.com/aa777m9k9vsh","Apply") | H26: Loose | I26: .NET — not Python | J26: Onsite/Hybrid | K26: Stretch (lead/8+) | L26: 168
A27: 26 | B27: Hashone Careers | C27: Backend AI Developer (Rust, Python) | D27: Remote | E27: Indeed | F27: 2026-06-11 | G27: =HYPERLINK("https://to.indeed.com/aanlxgttm7fr","Apply") | H27: Tight | I27: Backend + Python + AI | J27: Remote | K27: Ideal (3-6 yr) | L27: 63
A28: 27 | B28: Telesource Solutions | C28: Lead Backend Engineer | D28: Remote | E28: Indeed | F28: 2026-04-27 | G28: =HYPERLINK("https://to.indeed.com/aaq4ym9mvlc8","Apply") | H28: Tight | J28: Remote | K28: Stretch (lead/8+) | L28: 108
A29: 28 | B29: Garuda Spacex Technologies | C29: Senior Python Engineer / Backend Analytics | D29: Remote | E29: Indeed | F29: 2026-06-03 | G29: =HYPERLINK("https://to.indeed.com/aatnn9slnm9v","Apply") | H29: Tight | I29: Python + analytics + AI | J29: Remote | K29: Ideal (3-6 yr) | L29: 71
A30: 29 | B30: Echotech | C30: Sr. Python Developer | D30: Remote | E30: Indeed | F30: 2026-05-23 | G30: =HYPERLINK("https://to.indeed.com/aarbwym9kqst","Apply") | H30: Tight | J30: Remote | K30: Ideal (3-6 yr) | L30: 82
A31: 30 | B31: Enfec Solutions | C31: Senior Python Developer | D31: Remote | E31: Indeed | F31: 2026-04-22 | G31: =HYPERLINK("https://to.indeed.com/aamzhhzkm7cy","Apply") | H31: Tight | J31: Remote | K31: Ideal (3-6 yr) | L31: 113
A32: 31 | B32: Voicedots Infotech | C32: Senior Python Developer | D32: Remote | E32: Indeed | F32: 2026-05-04 | G32: =HYPERLINK("https://to.indeed.com/aa9sr8s4679r","Apply") | H32: Tight | J32: Remote | K32: Ideal (3-6 yr) | L32: 101
A33: 32 | B33: CloudiQS | C33: AWS Full Stack Developer + Agentic AI | D33: Remote | E33: Indeed | F33: 2026-03-14 | G33: =HYPERLINK("https://to.indeed.com/aapc72s8gxcx","Apply") | H33: Reasonable | I33: AWS + Agentic AI | J33: Remote | K33: Ideal (3-6 yr) | L33: 152
A34: 33 | B34: BuzzBoard | C34: Team Lead / Senior Specialist - AI | D34: Remote | E34: Indeed | F34: 2026-05-20 | G34: =HYPERLINK("https://to.indeed.com/aa2dsvvvpfsh","Apply") | H34: Reasonable | J34: Remote | K34: Stretch (lead/8+) | L34: 85
A35: 34 | B35: UB Realty Inc. | C35: Full-Stack (Next.js + Python) | D35: Remote | E35: Indeed | F35: 2026-06-11 | G35: =HYPERLINK("https://to.indeed.com/aak44vgzlxry","Apply") | H35: Reasonable | J35: Remote | K35: Ideal (3-6 yr) | L35: 63
A36: 35 | B36: Sparix Global | C36: Full Stack Developer | D36: Remote | E36: Indeed | F36: 2026-03-19 | G36: =HYPERLINK("https://to.indeed.com/aan2ywl9y4dn","Apply") | H36: Loose | J36: Remote | K36: Ideal (3-6 yr) | L36: 147
A37: 36 | B37: HelixBeat | C37: Full Stack Developer | D37: Remote | E37: Indeed | F37: 2026-04-23 | G37: =HYPERLINK("https://to.indeed.com/aabvzkcbbzcz","Apply") | H37: Loose | J37: Remote | K37: Ideal (3-6 yr) | L37: 112
A38: 37 | B38: Talent Vision Services | C38: Full Stack Developer | D38: Remote | E38: Indeed | F38: 2025-08-11 | G38: =HYPERLINK("https://to.indeed.com/aat26r76lqf7","Apply") | H38: Loose | J38: Remote | K38: Ideal (3-6 yr) | L38: 367
A39: 55 | B39: AppSquadz Software | C39: Senior AI Engineer (Backend & LLM Integration) | D39: Noida | E39: Indeed | F39: 2026-06-05 | G39: =HYPERLINK("https://to.indeed.com/aa9ldcdlxgrx","Apply") | H39: Tight | I39: ★ NEW Backend + LLM integration — strong agentic-AI fit | J39: Onsite/Hybrid | K39: Ideal (3-6 yr) | L39: 69
A40: 56 | B40: Avya Technology | C40: AI Agentic Engineer / AI Developer | D40: Noida | E40: Indeed | F40: 2026-06-04 | G40: =HYPERLINK("https://to.indeed.com/aamxxxbfvcyd","Apply") | H40: Tight | I40: ★ NEW Agentic AI — direct MCP/LangGraph match | J40: Onsite | K40: Ideal (3-6 yr) | L40: 70
...
